<?xml version="1.0"?>
<robot name="foo">

  <material name="blue">
    <color rgba="0 0 0.8 1"/>
  </material>

  <material name="white">
    <color rgba="1 1 1 1"/>
  </material>

  <link name="base_link">
    <visual>
      <geometry>
        <box size="0.2 0.2 1.2" />
      </geometry>
      <origin xyz="0 0 0.6" rpy="0 0 0"/>
      <material name="blue"/>
    </visual>
    <collision>
      <geometry>
        <box size="0.2 0.2 1.2" />
      </geometry>
      <origin xyz="0 0 0.6" rpy="0 0 0"/>
    </collision>
    <inertial>
      <mass value="10"/>
      <inertia ixx="1e-3" ixy="0.0" ixz="0.0" iyy="1e-3" iyz="0.0" izz="1e-3"/>
    </inertial>
  </link>

  <link name="bar">
    <visual>
      <geometry>
        <box size="0.2 0.2 1.2" />
      </geometry>
      <origin xyz="0.0 0.1 0.5" rpy="0 0 0"/>
      <material name="white"/>
    </visual>
    <collision>
      <geometry>
        <box size="0.2 0.2 1.2" />
      </geometry>
      <origin xyz="0.0 0.1 0.5" rpy="0 0 0"/>
    </collision>
    <inertial>
      <mass value="10"/>
      <inertia ixx="1e-3" ixy="0.0" ixz="0.0" iyy="1e-3" iyz="0.0" izz="1e-3"/>
    </inertial>
  </link>

  <joint name="base_to_bar" type="revolute">
    <parent link="base_link"/>
    <child link="bar"/>
    <origin xyz="0 0.1 1.1"/>
    <axis xyz="0 1 0"/>
    <limit effort="1000.0" lower="-3.14" upper="3.14" velocity="0.5"/>
  </joint>
  
</robot>
